Workbook

Sheet radiation_CR_2005_2023
A1: Latitude (decimal degrees): 38.960........
A2: Longitude (decimal degrees): -3.883........
A3: Elevation (m): 634.0........
A4: Irradiance Time Offset (h): 0.1686........
A5: month | B5: year.........
A6: 1 | B6: 2021.........
A7: 2 | B7: 2021.........
A8: 3 | B8: 2014.........
A9: 4 | B9: 202.........
A10: 5 | B10: 2008.........
A11: 6 | B11: 2021.........
A12: 7 | B12: 2013.........
A13: 8 | B13: 2011.........
A14: 9 | B14: 2022.........
A15: 10 | B15: 2012.........
A16: 11 | B16: 202.........
A17: 12 | B17: 2013.........
A18: time(UTC) | B18: T2m | C18: RH | D18: G(h) | E18: Gb(n) | F18: Gd(h) | G18: IR(h) | H18: WS10m | I18: WD10m | J18: SP.........
A19: 20210101-0000 | B19: 5.47 | C19: 82.99.0 | D19: -0.0.0 | E19: 327.24 | F19: 3.26 | G19: 256 | H19: 9336
A20: 20210101-0100 | B20: 4.94 | C20: 85.82.0 | D20: -0.0.0 | E20: 324.6 | F20: 3.47 | G20: 265 | H20: 9329
A21: 20210101-0200 | B21: 4.4 | C21: 88.66.0 | D21: -0.0.0 | E21: 32.88 | F21: 3.69 | G21: 266 | H21: 9326
A22: 20210101-0300 | B22: 3.87 | C22: 91.49.0 | D22: -0.0.0 | E22: 317.7 | F22: 3.9 | G22: 271 | H22: 9326
A23: 20210101-0400 | B23: 3.34 | C23: 94.32.0 | D23: -0.0.0 | E23: 314.53 | F23: 4.12 | G23: 273 | H23: 9327
A24: 20210101-0500 | B24: 2.81 | C24: 97.15.0 | D24: -0.0.0 | E24: 311.35 | F24: 4.33 | G24: 274 | H24: 9328
A25: 20210101-0600 | B25: 2.28 | C25: 99.98.0 | D25: -0.0.0 | E25: 308.17 | F25: 4.55 | G25: 275 | H25: 933
A26: 20210101-0700 | B26: 1.74 | C26: 1.0.0 | D26: -0.0.0 | E26: 304.99 | F26: 4.76 | G26: 278 | H26: 9329
A27: 20210101-0800 | B27: 2.17 | C27: 92.15 | D27: 61 | E27: 409.28 | F27: 25 | G27: 302.65 | H27: 3.24 | I27: 278 | J27: 9336
A28: 20210101-0900 | B28: 2.45 | C28: 95.7 | D28: 222 | E28: 69.35 | F28: 56 | G28: 312.35 | H28: 3.66 | I28: 282 | J28: 9341
A29: 20210101-1000 | B29: 3.5 | C29: 85.4 | D29: 338 | E29: 65.32 | F29: 104 | G29: 287.2 | H29: 3.93 | I29: 288 | J29: 9346
A30: 20210101-1100 | B30: 4.15 | C30: 79.15 | D30: 447 | E30: 822.7 | F30: 87 | G30: 279.45 | H30: 3.52 | I30: 293 | J30: 9347
A31: 20210101-1200 | B31: 4.93 | C31: 7.7 | D31: 49 | E31: 869.16 | F31: 82 | G31: 287.6 | H31: 3.45 | I31: 284 | J31: 9344
A32: 20210101-1300 | B32: 5.39 | C32: 65.55 | D32: 461 | E32: 811.62 | F32: 94 | G32: 296.5 | H32: 3.52 | I32: 275 | J32: 9335
A33: 20210101-1400 | B33: 5.72 | C33: 6.75 | D33: 3 | E33: 32.1 | F33: 176 | G33: 283.1 | H33: 3.79 | I33: 271 | J33: 9329
A34: 20210101-1500 | B34: 5.82 | C34: 56.2 | D34: 261 | E34: 708.58 | F34: 63 | G34: 273.85 | H34: 4.14 | I34: 273 | J34: 9329
A35: 20210101-1600 | B35: 5.45 | C35: 56.5 | D35: 107 | E35: 545.37 | F35: 33 | G35: 28.8 | H35: 4.7 | I35: 273 | J35: 9332
A36: 20210101-1700 | B36: 4.52 | C36: 62.8.0 | D36: -0.0.0 | E36: 262.5 | F36: 3.38 | G36: 27 | H36: 9336
A37: 20210101-1800 | B37: 3.82 | C37: 67.8.0 | D37: -0.0.0 | E37: 267.45 | F37: 3.1 | G37: 267 | H37: 934
A38: 20210101-1900 | B38: 3.33 | C38: 7.5.0 | D38: -0.0.0 | E38: 242.1 | F38: 3.24 | G38: 259 | H38: 934
A39: 20210101-2000 | B39: 2.63 | C39: 79.0.0 | D39: -0.0.0 | E39: 235.9 | F39: 3.17 | G39: 259 | H39: 9342
A40: 20210101-2100 | B40: 2.12 | C40: 82.5.0 | D40: -0.0.0 | E40: 237.5 | F40: 2.9 | G40: 262 | H40: 9348
...

Sheet Datos_procesados
A1: Fecha y Hora | B1: Fecha | C1: Fecha con formato | D1: Hora | E1: G(h) - W/m2 | F1: Consumo del sistema (Costo de tarea) Wh | G1: Corriente suministrada tomando el área calculada para el peor día de producción (mAH) | H1: Corriente que falta en cada lapso | I1: Corriente que entrega la batería | K1: Energía generada en el año (W/m2) | L1: Eficiencia del panel η1 | M1: Eficiencia del convertidor η2 | N1: Eficiencia del regulador η3 | O1: E(h)/A=G(h)×η1×η2×η3 (/m2) | P1: Energía consumida en el año (W) | Q1: E(h)=G(h)×A×η1×η2×η3 | R1: Área que debería tener para Energía cero al final del año | S1: Dimensión, suponiendo un panel cuadrado
A2: 20210101-0000 | B2: =LEFT(A2,8) -> 20210101 | C2: =DATE(LEFT(B2,4), MID(B2,5,2), RIGHT(B2,2)) -> 44197 | D2: =MID(A2,10,2) -> 00 | E2: 0 | F2: ='Costo de tareas'!$B$15 -> 0.19640278 | G2: ='Producción diaria'!$T$3*$L$2*$M$2*$N$2*E2*1000/'Costo de tareas'!$B$14 -> 0 | H2: =IF(G2 > 'Costo de tareas'!$B$13, 'Costo de tareas'!$B$13, IF(G2 < 'Costo de tareas'!$B$13*0.2, 0, 'Costo de tareas'!$B$13- G2)) -> 0 | I2: =IF(H2=0,'Costo de tareas'!$B$13,'Costo de tareas'!$B$13-H2) -> 39.280556 | K2: =SUM(E:E) -> 1620010.2 | L2: 0.24 | M2: 0.98 | N2: 0.85 | O2: =K2*L2*M2*N2 -> 323872.44 | P2: =SUM(F:F) -> 1720.4883 | R2: =P2/O2 -> 0.0053122407 | S2: =sqrt(R2) -> 0.07288512
A3: 20210101-0100 | B3: =LEFT(A3,8) -> 20210101 | C3: =DATE(LEFT(B3,4), MID(B3,5,2), RIGHT(B3,2)) -> 44197 | D3: =MID(A3,10,2) -> 01 | E3: 0 | F3: ='Costo de tareas'!$B$15 -> 0.19640278 | G3: ='Producción diaria'!$T$3*$L$2*$M$2*$N$2*E3*1000/'Costo de tareas'!$B$14 -> 0 | H3: =IF(G3 > 'Costo de tareas'!$B$13, 'Costo de tareas'!$B$13, IF(G3 < 'Costo de tareas'!$B$13*0.2, 0, 'Costo de tareas'!$B$13- G3)) -> 0 | I3: =IF(H3=0,'Costo de tareas'!$B$13,'Costo de tareas'!$B$13-H3) -> 39.280556 | S3: 8.4cm aprox?
A4: 20210101-0200 | B4: =LEFT(A4,8) -> 20210101 | C4: =DATE(LEFT(B4,4), MID(B4,5,2), RIGHT(B4,2)) -> 44197 | D4: =MID(A4,10,2) -> 02 | E4: 0 | F4: ='Costo de tareas'!$B$15 -> 0.19640278 | G4: ='Producción diaria'!$T$3*$L$2*$M$2*$N$2*E4*1000/'Costo de tareas'!$B$14 -> 0 | H4: =IF(G4 > 'Costo de tareas'!$B$13, 'Costo de tareas'!$B$13, IF(G4 < 'Costo de tareas'!$B$13*0.2, 0, 'Costo de tareas'!$B$13- G4)) -> 0 | I4: =IF(H4=0,'Costo de tareas'!$B$13,'Costo de tareas'!$B$13-H4) -> 39.280556
A5: 20210101-0300 | B5: =LEFT(A5,8) -> 20210101 | C5: =DATE(LEFT(B5,4), MID(B5,5,2), RIGHT(B5,2)) -> 44197 | D5: =MID(A5,10,2) -> 03 | E5: 0 | F5: ='Costo de tareas'!$B$15 -> 0.19640278 | G5: ='Producción diaria'!$T$3*$L$2*$M$2*$N$2*E5*1000/'Costo de tareas'!$B$14 -> 0 | H5: =IF(G5 > 'Costo de tareas'!$B$13, 'Costo de tareas'!$B$13, IF(G5 < 'Costo de tareas'!$B$13*0.2, 0, 'Costo de tareas'!$B$13- G5)) -> 0 | I5: =IF(H5=0,'Costo de tareas'!$B$13,'Costo de tareas'!$B$13-H5) -> 39.280556
A6: 20210101-0400 | B6: =LEFT(A6,8) -> 20210101 | C6: =DATE(LEFT(B6,4), MID(B6,5,2), RIGHT(B6,2)) -> 44197 | D6: =MID(A6,10,2) -> 04 | E6: 0 | F6: ='Costo de tareas'!$B$15 -> 0.19640278 | G6: ='Producción diaria'!$T$3*$L$2*$M$2*$N$2*E6*1000/'Costo de tareas'!$B$14 -> 0 | H6: =IF(G6 > 'Costo de tareas'!$B$13, 'Costo de tareas'!$B$13, IF(G6 < 'Costo de tareas'!$B$13*0.2, 0, 'Costo de tareas'!$B$13- G6)) -> 0 | I6: =IF(H6=0,'Costo de tareas'!$B$13,'Costo de tareas'!$B$13-H6) -> 39.280556
A7: 20210101-0500 | B7: =LEFT(A7,8) -> 20210101 | C7: =DATE(LEFT(B7,4), MID(B7,5,2), RIGHT(B7,2)) -> 44197 | D7: =MID(A7,10,2) -> 05 | E7: 0 | F7: ='Costo de tareas'!$B$15 -> 0.19640278 | G7: ='Producción diaria'!$T$3*$L$2*$M$2*$N$2*E7*1000/'Costo de tareas'!$B$14 -> 0 | H7: =IF(G7 > 'Costo de tareas'!$B$13, 'Costo de tareas'!$B$13, IF(G7 < 'Costo de tareas'!$B$13*0.2, 0, 'Costo de tareas'!$B$13- G7)) -> 0 | I7: =IF(H7=0,'Costo de tareas'!$B$13,'Costo de tareas'!$B$13-H7) -> 39.280556
A8: 20210101-0600 | B8: =LEFT(A8,8) -> 20210101 | C8: =DATE(LEFT(B8,4), MID(B8,5,2), RIGHT(B8,2)) -> 44197 | D8: =MID(A8,10,2) -> 06 | E8: 0 | F8: ='Costo de tareas'!$B$15 -> 0.19640278 | G8: ='Producción diaria'!$T$3*$L$2*$M$2*$N$2*E8*1000/'Costo de tareas'!$B$14 -> 0 | H8: =IF(G8 > 'Costo de tareas'!$B$13, 'Costo de tareas'!$B$13, IF(G8 < 'Costo de tareas'!$B$13*0.2, 0, 'Costo de tareas'!$B$13- G8)) -> 0 | I8: =IF(H8=0,'Costo de tareas'!$B$13,'Costo de tareas'!$B$13-H8) -> 39.280556
A9: 20210101-0700 | B9: =LEFT(A9,8) -> 20210101 | C9: =DATE(LEFT(B9,4), MID(B9,5,2), RIGHT(B9,2)) -> 44197 | D9: =MID(A9,10,2) -> 07 | E9: 0 | F9: ='Costo de tareas'!$B$15 -> 0.19640278 | G9: ='Producción diaria'!$T$3*$L$2*$M$2*$N$2*E9*1000/'Costo de tareas'!$B$14 -> 0 | H9: =IF(G9 > 'Costo de tareas'!$B$13, 'Costo de tareas'!$B$13, IF(G9 < 'Costo de tareas'!$B$13*0.2, 0, 'Costo de tareas'!$B$13- G9)) -> 0 | I9: =IF(H9=0,'Costo de tareas'!$B$13,'Costo de tareas'!$B$13-H9) -> 39.280556
A10: 20210101-0800 | B10: =LEFT(A10,8) -> 20210101 | C10: =DATE(LEFT(B10,4), MID(B10,5,2), RIGHT(B10,2)) -> 44197 | D10: =MID(A10,10,2) -> 08 | E10: 61 | F10: ='Costo de tareas'!$B$15 -> 0.19640278 | G10: ='Producción diaria'!$T$3*$L$2*$M$2*$N$2*E10*1000/'Costo de tareas'!$B$14 -> 91.717278 | H10: =IF(G10 > 'Costo de tareas'!$B$13, 'Costo de tareas'!$B$13, IF(G10 < 'Costo de tareas'!$B$13*0.2, 0, 'Costo de tareas'!$B$13- G10)) -> 39.280556 | I10: =IF(H10=0,'Costo de tareas'!$B$13,'Costo de tareas'!$B$13-H10) -> 0
A11: 20210101-0900 | B11: =LEFT(A11,8) -> 20210101 | C11: =DATE(LEFT(B11,4), MID(B11,5,2), RIGHT(B11,2)) -> 44197 | D11: =MID(A11,10,2) -> 09 | E11: 222 | F11: ='Costo de tareas'!$B$15 -> 0.19640278 | G11: ='Producción diaria'!$T$3*$L$2*$M$2*$N$2*E11*1000/'Costo de tareas'!$B$14 -> 333.79075 | H11: =IF(G11 > 'Costo de tareas'!$B$13, 'Costo de tareas'!$B$13, IF(G11 < 'Costo de tareas'!$B$13*0.2, 0, 'Costo de tareas'!$B$13- G11)) -> 39.280556 | I11: =IF(H11=0,'Costo de tareas'!$B$13,'Costo de tareas'!$B$13-H11) -> 0
A12: 20210101-1000 | B12: =LEFT(A12,8) -> 20210101 | C12: =DATE(LEFT(B12,4), MID(B12,5,2), RIGHT(B12,2)) -> 44197 | D12: =MID(A12,10,2) -> 10 | E12: 338 | F12: ='Costo de tareas'!$B$15 -> 0.19640278 | G12: ='Producción diaria'!$T$3*$L$2*$M$2*$N$2*E12*1000/'Costo de tareas'!$B$14 -> 508.20393 | H12: =IF(G12 > 'Costo de tareas'!$B$13, 'Costo de tareas'!$B$13, IF(G12 < 'Costo de tareas'!$B$13*0.2, 0, 'Costo de tareas'!$B$13- G12)) -> 39.280556 | I12: =IF(H12=0,'Costo de tareas'!$B$13,'Costo de tareas'!$B$13-H12) -> 0
A13: 20210101-1100 | B13: =LEFT(A13,8) -> 20210101 | C13: =DATE(LEFT(B13,4), MID(B13,5,2), RIGHT(B13,2)) -> 44197 | D13: =MID(A13,10,2) -> 11 | E13: 447 | F13: ='Costo de tareas'!$B$15 -> 0.19640278 | G13: ='Producción diaria'!$T$3*$L$2*$M$2*$N$2*E13*1000/'Costo de tareas'!$B$14 -> 672.09218 | H13: =IF(G13 > 'Costo de tareas'!$B$13, 'Costo de tareas'!$B$13, IF(G13 < 'Costo de tareas'!$B$13*0.2, 0, 'Costo de tareas'!$B$13- G13)) -> 39.280556 | I13: =IF(H13=0,'Costo de tareas'!$B$13,'Costo de tareas'!$B$13-H13) -> 0
A14: 20210101-1200 | B14: =LEFT(A14,8) -> 20210101 | C14: =DATE(LEFT(B14,4), MID(B14,5,2), RIGHT(B14,2)) -> 44197 | D14: =MID(A14,10,2) -> 12 | E14: 49 | F14: ='Costo de tareas'!$B$15 -> 0.19640278 | G14: ='Producción diaria'!$T$3*$L$2*$M$2*$N$2*E14*1000/'Costo de tareas'!$B$14 -> 73.674535 | H14: =IF(G14 > 'Costo de tareas'!$B$13, 'Costo de tareas'!$B$13, IF(G14 < 'Costo de tareas'!$B$13*0.2, 0, 'Costo de tareas'!$B$13- G14)) -> 39.280556 | I14: =IF(H14=0,'Costo de tareas'!$B$13,'Costo de tareas'!$B$13-H14) -> 0
A15: 20210101-1300 | B15: =LEFT(A15,8) -> 20210101 | C15: =DATE(LEFT(B15,4), MID(B15,5,2), RIGHT(B15,2)) -> 44197 | D15: =MID(A15,10,2) -> 13 | E15: 461 | F15: ='Costo de tareas'!$B$15 -> 0.19640278 | G15: ='Producción diaria'!$T$3*$L$2*$M$2*$N$2*E15*1000/'Costo de tareas'!$B$14 -> 693.14205 | H15: =IF(G15 > 'Costo de tareas'!$B$13, 'Costo de tareas'!$B$13, IF(G15 < 'Costo de tareas'!$B$13*0.2, 0, 'Costo de tareas'!$B$13- G15)) -> 39.280556 | I15: =IF(H15=0,'Costo de tareas'!$B$13,'Costo de tareas'!$B$13-H15) -> 0
... A8761: 20131231-2300 | B8761: =LEFT(A8761,8) -> 20131231 | C8761: =DATE(LEFT(B8761,4), MID(B8761,5,2), RIGHT(B8761,2)) -> 41639 | D8761: =MID(A8761,10,2) -> 23 | E8761: 0 | F8761: ='Costo de tareas'!$B$15 -> 0.19640278 | G8761: ='Producción diaria'!$T$3*$L$2*$M$2*$N$2*E8761*1000/'Costo de tareas'!$B$14 -> 0 | H8761: =IF(G8761 > 'Costo de tareas'!$B$13, 'Costo de tareas'!$B$13, IF(G8761 < 'Costo de tareas'!$B$13*0.2, 0, 'Costo de tareas'!$B$13- G8761)) -> 0 | I8761: =IF(H8761=0,'Costo de tareas'!$B$13,'Costo de tareas'!$B$13-H8761) -> 39.280556

Sheet Producción diaria
A1: Fechas únicas | B1: Irradiancia por día G(24h) | C1: Horas de sol de día | D1: Horas del sistema alimentado por batería | E1: Corriente necesaria de batería, con el consumo medio brindado (mA) | F1: Corriente suministrada por panel | G1: Corriente suministrada por batería | H1: Corriente consumida | I1: Mes y Año | J1: Meses y años | K1: Panel (mA) | L1: Panel (Watts) | M1: Batería (mA) | N1: Bateria (Watts) | Q1: G(24h) | R1: Fecha (si corresponde) | S1: Potencia disponible, luego de pérdidas (W/m2) | T1: Área calculada para consumo = Pd | U1: Dimensiones de un panel cuadrado (m) | W1: Eficiencia del panel η1 | X1: Eficiencia del convertidor η2 | Y1: Eficiencia del regulador η3 | AA1: Consumo estimado en 24hs (Watts)
A2: {=UNIQUE(Datos_procesados!C2:C366)} -> 44197 | B2: =SUMIF(Datos_procesados!C:C,A2,Datos_procesados!E:E) -> 1949 | C2: =COUNTIFS(Datos_procesados!C:C,A2,Datos_procesados!E:E, "<>0") -> 9 | D2: =24-C2 -> 15 | E2: =D2*'Costo de tareas'!$B$13 -> 589.20833 | F2: =SUMIF(Datos_procesados!C:C,A2,Datos_procesados!H:H) -> 314.24444 | G2: =SUMIF(Datos_procesados!C:C,A2,Datos_procesados!I:I) -> 628.48889 | H2: =sum(F2+G2) -> 942.73333 | I2: {=TEXT(A2:A366, "yyyy-mm")} -> 2021-01 | J2: {=UNIQUE(I2:I366)} -> 2021-01 | K2: =SUMIF(I:I,J2,F:F) -> 10914.356 | L2: =K2*'Costo de tareas'!$B$14/1000 -> 54.57178 | M2: =SUMIF(I:I,J2,G:G) -> 18310.377 | N2: =M2*'Costo de tareas'!$B$14/1000 -> 91.551886 | P2: Producción media diaria | Q2: =AVERAGE(B:B) -> 4438.3841 | S2: =Q2*W2*X2*Y2 -> 887.32174 | T2: =AA2/S2 -> 0.0053122407 | U2: =sqrt(T2) -> 0.07288512 | W2: =Datos_procesados!L2 -> 0.24 | X2: =Datos_procesados!M2 -> 0.98 | Y2: =Datos_procesados!N2 -> 0.85 | AA2: =24*'Costo de tareas'!B15 -> 4.7136667 | AN2: =24*'Costo de tareas'!B13 -> 942.73333
A3: 44198 | B3: =SUMIF(Datos_procesados!C:C,A3,Datos_procesados!E:E) -> 2426 | C3: =COUNTIFS(Datos_procesados!C:C,A3,Datos_procesados!E:E, "<>0") -> 9 | D3: =24-C3 -> 15 | E3: =D3*'Costo de tareas'!$B$13 -> 589.20833 | F3: =SUMIF(Datos_procesados!C:C,A3,Datos_procesados!H:H) -> 353.525 | G3: =SUMIF(Datos_procesados!C:C,A3,Datos_procesados!I:I) -> 589.20833 | H3: =sum(F3+G3) -> 942.73333 | I3: 2021-01 | J3: 2021-02 | K3: =SUMIF(I:I,J3,F:F) -> 10879.022 | L3: =K3*'Costo de tareas'!$B$14/1000 -> 54.395112 | M3: =SUMIF(I:I,J3,G:G) -> 15517.511 | N3: =M3*'Costo de tareas'!$B$14/1000 -> 77.587555 | P3: Producción miníma | Q3: =MIN(B:B) -> 627 | R3: 44204 | S3: =Q3*W2*X2*Y2 -> 125.34984 | T3: =AA2/S3 -> 0.03760409 | U3: =sqrt(T3) -> 0.19391774
A4: 44199 | B4: =SUMIF(Datos_procesados!C:C,A4,Datos_procesados!E:E) -> 2433 | C4: =COUNTIFS(Datos_procesados!C:C,A4,Datos_procesados!E:E, "<>0") -> 9 | D4: =24-C4 -> 15 | E4: =D4*'Costo de tareas'!$B$13 -> 589.20833 | F4: =SUMIF(Datos_procesados!C:C,A4,Datos_procesados!H:H) -> 353.525 | G4: =SUMIF(Datos_procesados!C:C,A4,Datos_procesados!I:I) -> 589.20833 | H4: =sum(F4+G4) -> 942.73333 | I4: 2021-01 | J4: 2014-03 | K4: =SUMIF(I:I,J4,F:F) -> 13642.381 | L4: =K4*'Costo de tareas'!$B$14/1000 -> 68.211906 | M4: =SUMIF(I:I,J4,G:G) -> 15582.352 | N4: =M4*'Costo de tareas'!$B$14/1000 -> 77.91176 | P4: Producción máxima | Q4: =MAX(B:B) -> 8818.4 | R4: 41466 | S4: =Q4*W2*X2*Y2 -> 1762.9745 | T4: =AA2/S4 -> 0.0026737009 | U4: =sqrt(T4) -> 0.051707842
A5: 44200 | B5: =SUMIF(Datos_procesados!C:C,A5,Datos_procesados!E:E) -> 1222 | C5: =COUNTIFS(Datos_procesados!C:C,A5,Datos_procesados!E:E, "<>0") -> 9 | D5: =24-C5 -> 15 | E5: =D5*'Costo de tareas'!$B$13 -> 589.20833 | F5: =SUMIF(Datos_procesados!C:C,A5,Datos_procesados!H:H) -> 314.24444 | G5: =SUMIF(Datos_procesados!C:C,A5,Datos_procesados!I:I) -> 628.48889 | H5: =sum(F5+G5) -> 942.73333 | I5: 2021-01 | J5: 2020-04 | K5: =SUMIF(I:I,J5,F:F) -> 14319.548 | L5: =K5*'Costo de tareas'!$B$14/1000 -> 71.59774 | M5: =SUMIF(I:I,J5,G:G) -> 13962.452 | N5: =M5*'Costo de tareas'!$B$14/1000 -> 69.81226
A6: 44201 | B6: =SUMIF(Datos_procesados!C:C,A6,Datos_procesados!E:E) -> 1679 | C6: =COUNTIFS(Datos_procesados!C:C,A6,Datos_procesados!E:E, "<>0") -> 9 | D6: =24-C6 -> 15 | E6: =D6*'Costo de tareas'!$B$13 -> 589.20833 | F6: =SUMIF(Datos_procesados!C:C,A6,Datos_procesados!H:H) -> 335.48226 | G6: =SUMIF(Datos_procesados!C:C,A6,Datos_procesados!I:I) -> 607.25108 | H6: =sum(F6+G6) -> 942.73333 | I6: 2021-01 | J6: 2008-05 | K6: =SUMIF(I:I,J6,F:F) -> 16435.436 | L6: =K6*'Costo de tareas'!$B$14/1000 -> 82.177178 | M6: =SUMIF(I:I,J6,G:G) -> 12789.298 | N6: =M6*'Costo de tareas'!$B$14/1000 -> 63.946489
A7: 44202 | B7: =SUMIF(Datos_procesados!C:C,A7,Datos_procesados!E:E) -> 2380 | C7: =COUNTIFS(Datos_procesados!C:C,A7,Datos_procesados!E:E, "<>0") -> 9 | D7: =24-C7 -> 15 | E7: =D7*'Costo de tareas'!$B$13 -> 589.20833 | F7: =SUMIF(Datos_procesados!C:C,A7,Datos_procesados!H:H) -> 353.525 | G7: =SUMIF(Datos_procesados!C:C,A7,Datos_procesados!I:I) -> 589.20833 | H7: =sum(F7+G7) -> 942.73333 | I7: 2021-01 | J7: 2021-06 | K7: =SUMIF(I:I,J7,F:F) -> 16098.074 | L7: =K7*'Costo de tareas'!$B$14/1000 -> 80.490369 | M7: =SUMIF(I:I,J7,G:G) -> 12183.926 | N7: =M7*'Costo de tareas'!$B$14/1000 -> 60.919631 | Q7: Enlace de la explicación para realizar los calculos necesarios para batería y demás
A8: 44203 | B8: =SUMIF(Datos_procesados!C:C,A8,Datos_procesados!E:E) -> 686 | C8: =COUNTIFS(Datos_procesados!C:C,A8,Datos_procesados!E:E, "<>0") -> 9 | D8: =24-C8 -> 15 | E8: =D8*'Costo de tareas'!$B$13 -> 589.20833 | F8: =SUMIF(Datos_procesados!C:C,A8,Datos_procesados!H:H) -> 329.46801 | G8: =SUMIF(Datos_procesados!C:C,A8,Datos_procesados!I:I) -> 613.26532 | H8: =sum(F8+G8) -> 942.73333 | I8: 2021-01 | J8: 2013-07 | K8: =SUMIF(I:I,J8,F:F) -> 16744.605 | L8: =K8*'Costo de tareas'!$B$14/1000 -> 83.723027 | M8: =SUMIF(I:I,J8,G:G) -> 12480.128 | N8: =M8*'Costo de tareas'!$B$14/1000 -> 62.400639 | Q8: ¿Cómo calcular el panel solar y la batería para Starlink? - Edgeware Technology
A9: 44204 | B9: =SUMIF(Datos_procesados!C:C,A9,Datos_procesados!E:E) -> 627 | C9: =COUNTIFS(Datos_procesados!C:C,A9,Datos_procesados!E:E, "<>0") -> 9 | D9: =24-C9 -> 15 | E9: =D9*'Costo de tareas'!$B$13 -> 589.20833 | F9: =SUMIF(Datos_procesados!C:C,A9,Datos_procesados!H:H) -> 336.98582 | G9: =SUMIF(Datos_procesados!C:C,A9,Datos_procesados!I:I) -> 605.74751 | H9: =sum(F9+G9) -> 942.73333 | I9: 2021-01 | J9: 2011-08 | K9: =SUMIF(I:I,J9,F:F) -> 15884.38 | L9: =K9*'Costo de tareas'!$B$14/1000 -> 79.4219 | M9: =SUMIF(I:I,J9,G:G) -> 13340.353 | N9: =M9*'Costo de tareas'!$B$14/1000 -> 66.701766
A10: 44205 | B10: =SUMIF(Datos_procesados!C:C,A10,Datos_procesados!E:E) -> 905 | C10: =COUNTIFS(Datos_procesados!C:C,A10,Datos_procesados!E:E, "<>0") -> 9 | D10: =24-C10 -> 15 | E10: =D10*'Costo de tareas'!$B$13 -> 589.20833 | F10: =SUMIF(Datos_procesados!C:C,A10,Datos_procesados!H:H) -> 321.9502 | G10: =SUMIF(Datos_procesados!C:C,A10,Datos_procesados!I:I) -> 620.78313 | H10: =sum(F10+G10) -> 942.73333 | I10: 2021-01 | J10: 2022-09 | K10: =SUMIF(I:I,J10,F:F) -> 14041.577 | L10: =K10*'Costo de tareas'!$B$14/1000 -> 70.207885 | M10: =SUMIF(I:I,J10,G:G) -> 14240.423 | N10: =M10*'Costo de tareas'!$B$14/1000 -> 71.202115 | Q10: La batería debería tener la capacidad de brindar la energía necesaria para las horas del día que el sistema se encuentra sin sol.
A11: 44206 | B11: =SUMIF(Datos_procesados!C:C,A11,Datos_procesados!E:E) -> 2927 | C11: =COUNTIFS(Datos_procesados!C:C,A11,Datos_procesados!E:E, "<>0") -> 9 | D11: =24-C11 -> 15 | E11: =D11*'Costo de tareas'!$B$13 -> 589.20833 | F11: =SUMIF(Datos_procesados!C:C,A11,Datos_procesados!H:H) -> 353.525 | G11: =SUMIF(Datos_procesados!C:C,A11,Datos_procesados!I:I) -> 589.20833 | H11: =sum(F11+G11) -> 942.73333 | I11: 2021-01 | J11: 2012-10 | K11: =SUMIF(I:I,J11,F:F) -> 12722.577 | L11: =K11*'Costo de tareas'!$B$14/1000 -> 63.612886 | M11: =SUMIF(I:I,J11,G:G) -> 16502.156 | N11: =M11*'Costo de tareas'!$B$14/1000 -> 82.51078
A12: 44207 | B12: =SUMIF(Datos_procesados!C:C,A12,Datos_procesados!E:E) -> 2615 | C12: =COUNTIFS(Datos_procesados!C:C,A12,Datos_procesados!E:E, "<>0") -> 9 | D12: =24-C12 -> 15 | E12: =D12*'Costo de tareas'!$B$13 -> 589.20833 | F12: =SUMIF(Datos_procesados!C:C,A12,Datos_procesados!H:H) -> 353.525 | G12: =SUMIF(Datos_procesados!C:C,A12,Datos_procesados!I:I) -> 589.20833 | H12: =sum(F12+G12) -> 942.73333 | I12: 2021-01 | J12: 2020-11 | K12: =SUMIF(I:I,J12,F:F) -> 10627.364 | L12: =K12*'Costo de tareas'!$B$14/1000 -> 53.136819 | M12: =SUMIF(I:I,J12,G:G) -> 17654.636 | N12: =M12*'Costo de tareas'!$B$14/1000 -> 88.273181
A13: 44208 | B13: =SUMIF(Datos_procesados!C:C,A13,Datos_procesados!E:E) -> 2663 | C13: =COUNTIFS(Datos_procesados!C:C,A13,Datos_procesados!E:E, "<>0") -> 9 | D13: =24-C13 -> 15 | E13: =D13*'Costo de tareas'!$B$13 -> 589.20833 | F13: =SUMIF(Datos_procesados!C:C,A13,Datos_procesados!H:H) -> 353.525 | G13: =SUMIF(Datos_procesados!C:C,A13,Datos_procesados!I:I) -> 589.20833 | H13: =sum(F13+G13) -> 942.73333 | I13: 2021-01 | J13: 2013-12 | K13: =SUMIF(I:I,J13,F:F) -> 10626.236 | L13: =K13*'Costo de tareas'!$B$14/1000 -> 53.13118 | M13: =SUMIF(I:I,J13,G:G) -> 18598.497 | N13: =M13*'Costo de tareas'!$B$14/1000 -> 92.992487 | Q13: El tamaño del panel solar suele calcularse para aportar la energía que requiere el sistema, pero también para cargar la batería. Es decir, P_panel = P_sistema+P_bateria
A14: 44209 | B14: =SUMIF(Datos_procesados!C:C,A14,Datos_procesados!E:E) -> 2913 | C14: =COUNTIFS(Datos_procesados!C:C,A14,Datos_procesados!E:E, "<>0") -> 9 | D14: =24-C14 -> 15 | E14: =D14*'Costo de tareas'!$B$13 -> 589.20833 | F14: =SUMIF(Datos_procesados!C:C,A14,Datos_procesados!H:H) -> 318.94308 | G14: =SUMIF(Datos_procesados!C:C,A14,Datos_procesados!I:I) -> 623.79026 | H14: =sum(F14+G14) -> 942.73333 | I14: 2021-01
A15: 44210 | B15: =SUMIF(Datos_procesados!C2:C366,A15,Datos_procesados!E2:E366) -> 2456.95 | C15: =COUNTIFS(Datos_procesados!C:C,A15,Datos_procesados!E:E, "<>0") -> 10 | D15: =24-C15 -> 14 | E15: =D15*'Costo de tareas'!$B$13 -> 549.92778 | F15: =SUMIF(Datos_procesados!C:C,A15,Datos_procesados!H:H) -> 392.80556 | G15: =SUMIF(Datos_procesados!C:C,A15,Datos_procesados!I:I) -> 549.92778 | H15: =sum(F15+G15) -> 942.73333 | I15: 2021-01
A16: 44211 | B16: =SUMIF(Datos_procesados!C:C,A16,Datos_procesados!E:E) -> 3266.5 | C16: =COUNTIFS(Datos_procesados!C:C,A16,Datos_procesados!E:E, "<>0") -> 10 | D16: =24-C16 -> 14 | E16: =D16*'Costo de tareas'!$B$13 -> 549.92778 | F16: =SUMIF(Datos_procesados!C:C,A16,Datos_procesados!H:H) -> 392.80556 | G16: =SUMIF(Datos_procesados!C:C,A16,Datos_procesados!I:I) -> 549.92778 | H16: =sum(F16+G16) -> 942.73333 | I16: 2021-01 | Q16: Para no dañar la batería, se suele utilizar solamente hasta el 80% de la capacidad que provee. Es decir, equivale a sobredimensionar la batería un 20%
A17: 44212 | B17: =SUMIF(Datos_procesados!C:C,A17,Datos_procesados!E:E) -> 2932 | C17: =COUNTIFS(Datos_procesados!C:C,A17,Datos_procesados!E:E, "<>0") -> 10 | D17: =24-C17 -> 14 | E17: =D17*'Costo de tareas'!$B$13 -> 549.92778 | F17: =SUMIF(Datos_procesados!C:C,A17,Datos_procesados!H:H) -> 392.80556 | G17: =SUMIF(Datos_procesados!C:C,A17,Datos_procesados!I:I) -> 549.92778 | H17: =sum(F17+G17) -> 942.73333 | I17: 2021-01
A18: 44213 | B18: =SUMIF(Datos_procesados!C:C,A18,Datos_procesados!E:E) -> 2893.25 | C18: =COUNTIFS(Datos_procesados!C:C,A18,Datos_procesados!E:E, "<>0") -> 10 | D18: =24-C18 -> 14 | E18: =D18*'Costo de tareas'!$B$13 -> 549.92778 | F18: =SUMIF(Datos_procesados!C:C,A18,Datos_procesados!H:H) -> 368.74856 | G18: =SUMIF(Datos_procesados!C:C,A18,Datos_procesados!I:I) -> 573.98477 | H18: =sum(F18+G18) -> 942.73333 | I18: 2021-01
A19: 44214 | B19: =SUMIF(Datos_procesados!C:C,A19,Datos_procesados!E:E) -> 2575.6 | C19: =COUNTIFS(Datos_procesados!C:C,A19,Datos_procesados!E:E, "<>0") -> 10 | D19: =24-C19 -> 14 | E19: =D19*'Costo de tareas'!$B$13 -> 549.92778 | F19: =SUMIF(Datos_procesados!C:C,A19,Datos_procesados!H:H) -> 392.80556 | G19: =SUMIF(Datos_procesados!C:C,A19,Datos_procesados!I:I) -> 549.92778 | H19: =sum(F19+G19) -> 942.73333 | I19: 2021-01 | Q19: Los datos descargados son de: https://re.jrc.ec.europa.eu/pvg_tools/en/#MR
A20: 44215 | B20: =SUMIF(Datos_procesados!C:C,A20,Datos_procesados!E:E) -> 3018.1 | C20: =COUNTIFS(Datos_procesados!C:C,A20,Datos_procesados!E:E, "<>0") -> 10 | D20: =24-C20 -> 14 | E20: =D20*'Costo de tareas'!$B$13 -> 549.92778 | F20: =SUMIF(Datos_procesados!C:C,A20,Datos_procesados!H:H) -> 368.74856 | G20: =SUMIF(Datos_procesados!C:C,A20,Datos_procesados!I:I) -> 573.98477 | H20: =sum(F20+G20) -> 942.73333 | I20: 2021-01
A21: 44216 | B21: =SUMIF(Datos_procesados!C:C,A21,Datos_procesados!E:E) -> 1308.75 | C21: =COUNTIFS(Datos_procesados!C:C,A21,Datos_procesados!E:E, "<>0") -> 10 | D21: =24-C21 -> 14 | E21: =D21*'Costo de tareas'!$B$13 -> 549.92778 | F21: =SUMIF(Datos_procesados!C:C,A21,Datos_procesados!H:H) -> 380.77706 | G21: =SUMIF(Datos_procesados!C:C,A21,Datos_procesados!I:I) -> 561.95627 | H21: =sum(F21+G21) -> 942.73333 | I21: 2021-01
A22: 44217 | B22: =SUMIF(Datos_procesados!C:C,A22,Datos_procesados!E:E) -> 2030.75 | C22: =COUNTIFS(Datos_procesados!C:C,A22,Datos_procesados!E:E, "<>0") -> 10 | D22: =24-C22 -> 14 | E22: =D22*'Costo de tareas'!$B$13 -> 549.92778 | F22: =SUMIF(Datos_procesados!C:C,A22,Datos_procesados!H:H) -> 379.2735 | G22: =SUMIF(Datos_procesados!C:C,A22,Datos_procesados!I:I) -> 563.45984 | H22: =sum(F22+G22) -> 942.73333 | I22: 2021-01 | S22: =RIGHT(Q23,4)
A23: 44218 | B23: =SUMIF(Datos_procesados!C:C,A23,Datos_procesados!E:E) -> 1501 | C23: =COUNTIFS(Datos_procesados!C:C,A23,Datos_procesados!E:E, "<>0") -> 10 | D23: =24-C23 -> 14 | E23: =D23*'Costo de tareas'!$B$13 -> 549.92778 | F23: =SUMIF(Datos_procesados!C:C,A23,Datos_procesados!H:H) -> 317.43951 | G23: =SUMIF(Datos_procesados!C:C,A23,Datos_procesados!I:I) -> 625.29382 | H23: =sum(F23+G23) -> 942.73333 | I23: 2021-01 | R23: =LEFT(Q23,8) | S23: =RIGHT(Q24,4)
A24: 44219 | B24: =SUMIF(Datos_procesados!C:C,A24,Datos_procesados!E:E) -> 1638 | C24: =COUNTIFS(Datos_procesados!C:C,A24,Datos_procesados!E:E, "<>0") -> 10 | D24: =24-C24 -> 14 | E24: =D24*'Costo de tareas'!$B$13 -> 549.92778 | F24: =SUMIF(Datos_procesados!C:C,A24,Datos_procesados!H:H) -> 353.525 | G24: =SUMIF(Datos_procesados!C:C,A24,Datos_procesados!I:I) -> 589.20833 | H24: =sum(F24+G24) -> 942.73333 | I24: 2021-01 | R24: =LEFT(Q24,8)
A25: 44220 | B25: =SUMIF(Datos_procesados!C:C,A25,Datos_procesados!E:E) -> 1839 | C25: =COUNTIFS(Datos_procesados!C:C,A25,Datos_procesados!E:E, "<>0") -> 10 | D25: =24-C25 -> 14 | E25: =D25*'Costo de tareas'!$B$13 -> 549.92778 | F25: =SUMIF(Datos_procesados!C:C,A25,Datos_procesados!H:H) -> 326.46089 | G25: =SUMIF(Datos_procesados!C:C,A25,Datos_procesados!I:I) -> 616.27245 | H25: =sum(F25+G25) -> 942.73333 | I25: 2021-01
A26: 44221 | B26: =SUMIF(Datos_procesados!C:C,A26,Datos_procesados!E:E) -> 1144 | C26: =COUNTIFS(Datos_procesados!C:C,A26,Datos_procesados!E:E, "<>0") -> 10 | D26: =24-C26 -> 14 | E26: =D26*'Costo de tareas'!$B$13 -> 549.92778 | F26: =SUMIF(Datos_procesados!C:C,A26,Datos_procesados!H:H) -> 326.46089 | G26: =SUMIF(Datos_procesados!C:C,A26,Datos_procesados!I:I) -> 616.27245 | H26: =sum(F26+G26) -> 942.73333 | I26: 2021-01
A27: 44222 | B27: =SUMIF(Datos_procesados!C:C,A27,Datos_procesados!E:E) -> 1337 | C27: =COUNTIFS(Datos_procesados!C:C,A27,Datos_procesados!E:E, "<>0") -> 10 | D27: =24-C27 -> 14 | E27: =D27*'Costo de tareas'!$B$13 -> 549.92778 | F27: =SUMIF(Datos_procesados!C:C,A27,Datos_procesados!H:H) -> 353.525 | G27: =SUMIF(Datos_procesados!C:C,A27,Datos_procesados!I:I) -> 589.20833 | H27: =sum(F27+G27) -> 942.73333 | I27: 2021-01
A28: 44223 | B28: =SUMIF(Datos_procesados!C:C,A28,Datos_procesados!E:E) -> 2018 | C28: =COUNTIFS(Datos_procesados!C:C,A28,Datos_procesados!E:E, "<>0") -> 10 | D28: =24-C28 -> 14 | E28: =D28*'Costo de tareas'!$B$13 -> 549.92778 | F28: =SUMIF(Datos_procesados!C:C,A28,Datos_procesados!H:H) -> 379.2735 | G28: =SUMIF(Datos_procesados!C:C,A28,Datos_procesados!I:I) -> 563.45984 | H28: =sum(F28+G28) -> 942.73333 | I28: 2021-01
A29: 44224 | B29: =SUMIF(Datos_procesados!C:C,A29,Datos_procesados!E:E) -> 2635 | C29: =COUNTIFS(Datos_procesados!C:C,A29,Datos_procesados!E:E, "<>0") -> 10 | D29: =24-C29 -> 14 | E29: =D29*'Costo de tareas'!$B$13 -> 549.92778 | F29: =SUMIF(Datos_procesados!C:C,A29,Datos_procesados!H:H) -> 370.25213 | G29: =SUMIF(Datos_procesados!C:C,A29,Datos_procesados!I:I) -> 572.48121 | H29: =sum(F29+G29) -> 942.73333 | I29: 2021-01
A30: 44225 | B30: =SUMIF(Datos_procesados!C:C,A30,Datos_procesados!E:E) -> 3497 | C30: =COUNTIFS(Datos_procesados!C:C,A30,Datos_procesados!E:E, "<>0") -> 10 | D30: =24-C30 -> 14 | E30: =D30*'Costo de tareas'!$B$13 -> 549.92778 | F30: =SUMIF(Datos_procesados!C:C,A30,Datos_procesados!H:H) -> 370.25213 | G30: =SUMIF(Datos_procesados!C:C,A30,Datos_procesados!I:I) -> 572.48121 | H30: =sum(F30+G30) -> 942.73333 | I30: 2021-01
A31: 44226 | B31: =SUMIF(Datos_procesados!C:C,A31,Datos_procesados!E:E) -> 2588 | C31: =COUNTIFS(Datos_procesados!C:C,A31,Datos_procesados!E:E, "<>0") -> 10 | D31: =24-C31 -> 14 | E31: =D31*'Costo de tareas'!$B$13 -> 549.92778 | F31: =SUMIF(Datos_procesados!C:C,A31,Datos_procesados!H:H) -> 320.44664 | G31: =SUMIF(Datos_procesados!C:C,A31,Datos_procesados!I:I) -> 622.2867 | H31: =sum(F31+G31) -> 942.73333 | I31: 2021-01
A32: 44227 | B32: =SUMIF(Datos_procesados!C:C,A32,Datos_procesados!E:E) -> 1142 | C32: =COUNTIFS(Datos_procesados!C:C,A32,Datos_procesados!E:E, "<>0") -> 10 | D32: =24-C32 -> 14 | E32: =D32*'Costo de tareas'!$B$13 -> 549.92778 | F32: =SUMIF(Datos_procesados!C:C,A32,Datos_procesados!H:H) -> 335.48226 | G32: =SUMIF(Datos_procesados!C:C,A32,Datos_procesados!I:I) -> 607.25108 | H32: =sum(F32+G32) -> 942.73333 | I32: 2021-01
A33: 44228 | B33: =SUMIF(Datos_procesados!C:C,A33,Datos_procesados!E:E) -> 2021 | C33: =COUNTIFS(Datos_procesados!C:C,A33,Datos_procesados!E:E, "<>0") -> 10 | D33: =24-C33 -> 14 | E33: =D33*'Costo de tareas'!$B$13 -> 549.92778 | F33: =SUMIF(Datos_procesados!C:C,A33,Datos_procesados!H:H) -> 376.26637 | G33: =SUMIF(Datos_procesados!C:C,A33,Datos_procesados!I:I) -> 566.46696 | H33: =sum(F33+G33) -> 942.73333 | I33: 2021-02
A34: 44229 | B34: =SUMIF(Datos_procesados!C:C,A34,Datos_procesados!E:E) -> 1767 | C34: =COUNTIFS(Datos_procesados!C:C,A34,Datos_procesados!E:E, "<>0") -> 10 | D34: =24-C34 -> 14 | E34: =D34*'Costo de tareas'!$B$13 -> 549.92778 | F34: =SUMIF(Datos_procesados!C:C,A34,Datos_procesados!H:H) -> 373.25925 | G34: =SUMIF(Datos_procesados!C:C,A34,Datos_procesados!I:I) -> 569.47408 | H34: =sum(F34+G34) -> 942.73333 | I34: 2021-02
A35: 44230 | B35: =SUMIF(Datos_procesados!C:C,A35,Datos_procesados!E:E) -> 2349 | C35: =COUNTIFS(Datos_procesados!C:C,A35,Datos_procesados!E:E, "<>0") -> 10 | D35: =24-C35 -> 14 | E35: =D35*'Costo de tareas'!$B$13 -> 549.92778 | F35: =SUMIF(Datos_procesados!C:C,A35,Datos_procesados!H:H) -> 335.6702 | G35: =SUMIF(Datos_procesados!C:C,A35,Datos_procesados!I:I) -> 607.06313 | H35: =sum(F35+G35) -> 942.73333 | I35: 2021-02
A36: 44231 | B36: =SUMIF(Datos_procesados!C:C,A36,Datos_procesados!E:E) -> 1530 | C36: =COUNTIFS(Datos_procesados!C:C,A36,Datos_procesados!E:E, "<>0") -> 10 | D36: =24-C36 -> 14 | E36: =D36*'Costo de tareas'!$B$13 -> 549.92778 | F36: =SUMIF(Datos_procesados!C:C,A36,Datos_procesados!H:H) -> 337.17376 | G36: =SUMIF(Datos_procesados!C:C,A36,Datos_procesados!I:I) -> 605.55957 | H36: =sum(F36+G36) -> 942.73333 | I36: 2021-02
... A366: 41639 | B366: =SUMIF(Datos_procesados!C:C,A366,Datos_procesados!E:E) -> 1717 | C366: =COUNTIFS(Datos_procesados!C:C,A366,Datos_procesados!E:E, "<>0") -> 9 | D366: =24-C366 -> 15 | E366: =D366*'Costo de tareas'!$B$13 -> 589.20833 | F366: =SUMIF(Datos_procesados!C:C,A366,Datos_procesados!H:H) -> 314.24444 | G366: =SUMIF(Datos_procesados!C:C,A366,Datos_procesados!I:I) -> 628.48889 | H366: =sum(F366+G366) -> 942.73333 | I366: 2013-12

Sheet Producción mensual
A1: Fechas únicas | B1: Mes al correo | C1: {=UNIQUE(B:B)} -> Mes al correo
A2: 44197 | B2: =MONTH(A:A) -> 1 | C2: 1
A3: 44198 | B3: =MONTH(A:A) -> 1 | C3: 2
A4: 44199 | B4: =MONTH(A:A) -> 1 | C4: 3
A5: 44200 | B5: =MONTH(A:A) -> 1 | C5: 4
A6: 44201 | B6: =MONTH(A:A) -> 1 | C6: 5
A7: 44202 | B7: =MONTH(A:A) -> 1 | C7: 6
A8: 44203 | B8: =MONTH(A:A) -> 1 | C8: 7
A9: 44204 | B9: =MONTH(A:A) -> 1 | C9: 8
A10: 44205 | B10: =MONTH(A:A) -> 1 | C10: 9
A11: 44206 | B11: =MONTH(A:A) -> 1 | C11: 10
A12: 44207 | B12: =MONTH(A:A) -> 1 | C12: 11
A13: 44208 | B13: =MONTH(A:A) -> 1 | C13: 12
A14: 44209 | B14: =MONTH(A:A) -> 1
A15: 44210 | B15: =MONTH(A:A) -> 1
A16: 44211 | B16: =MONTH(A:A) -> 1
A17: 44212 | B17: =MONTH(A:A) -> 1
A18: 44213 | B18: =MONTH(A:A) -> 1
A19: 44214 | B19: =MONTH(A:A) -> 1
A20: 44215 | B20: =MONTH(A:A) -> 1
A21: 44216 | B21: =MONTH(A:A) -> 1
A22: 44217 | B22: =MONTH(A:A) -> 1
A23: 44218 | B23: =MONTH(A:A) -> 1
A24: 44219 | B24: =MONTH(A:A) -> 1
A25: 44220 | B25: =MONTH(A:A) -> 1
... A366: 41639 | B366: =MONTH(A:A) -> 12

Sheet Costo de tareas
A1: Tarea | B1: Consumo (mA) | C1: Tiempo de tarea (seg) | D1: Porcentaje | E1: Consumo según porcentaje (mA) | H1: Valores que se pueden modificar
A2: Tarea 1 | B2: =I4 -> 28 | C2: =I3-sum(C3:C8) -> 2375 | D2: =C2/3600 -> 0.65972222 | E2: =B2*D2 -> 18.472222 | H2: Muestras por hora | I2: 10
A3: Tarea 2 | B3: =I5 -> 36 | D3: =C3/3600 -> 0 | E3: =B3*D3 -> 0 | H3: Tiempo por slot (seg) | I3: 3600
A4: Tarea 3 | B4: =I6 -> 44 | D4: =C4/3600 -> 0 | E4: =B4*D4 -> 0 | H4: Tarea 1 (mA) | I4: 28 | J4: Pico On - Resto sleep
A5: Tarea 4 | B5: =I7 -> 52 | D5: =C5/3600 -> 0 | E5: =B5*D5 -> 0 | H5: Tarea 2 (mA) | I5: =I4+8 -> 36 | J5: Pico On - 1 Sensor On
A6: Tarea 5 | B6: =I8 -> 60 | C6: =120*I2 -> 1200 | D6: =C6/3600 -> 0.33333333 | E6: =B6*D6 -> 20 | H6: Tarea 3 (mA) | I6: =I5+8 -> 44 | J6: Pico On - 2 Sensor On
A7: Tarea 6 | B7: =I9 -> 128 | C7: =2*I2 -> 20 | D7: =C7/3600 -> 0.0055555556 | E7: =B7*D7 -> 0.71111111 | H7: Tarea 4 (mA) | I7: =I6+8 -> 52 | J7: Pico On - 3 Sensor On
A8: Tarea 7 | B8: =I10 -> 70 | C8: =0.5*I2 -> 5 | D8: =C8/3600 -> 0.0013888889 | E8: =B8*D8 -> 0.097222222 | H8: Tarea 5 (mA) | I8: =I7+8 -> 60 | J8: Pico On - 4 Sensor On
H9: Tarea 6 (mA) | I9: =I4+100 -> 128 | J9: Pico On - Particulas On
H10: Tarea 7 (mA) | I10: 70 | J10: Pico On - Tx - Resto Off
A12: Resultados
A13: Consumo promedio por hora (mA) | B13: =sum(E2:E8) -> 39.280556 | C13: mA
A14: Alimentación del sistema | B14: 5 | C14: V
A15: Potencia consumida | B15: =B14*B13/1000 -> 0.19640278 | C15: Watts
